import sys
import traceback
import logging

from discord.ext import commands
import discord


class CommandErrorHandler(commands.Cog):
    def __init__(self, bot):
        self.bot = bot

    @staticmethod
    async def delete_after(msg: discord.Message, second: int = 5):
        """渡されたメッセージを指定秒数後に削除する関数

        Args:
            msg (discord.Message): 削除するメッセージオブジェクト
            second (int, optional): 秒数. Defaults to 5.
        """
        try:
            await msg.delete(delay=second)
        except discord.Forbidden:
            pass

    @commands.Cog.listener()
    async def on_command_error(self, ctx, error):
        """The event triggered when an error is raised while invoking a command.
        ctx   : Context
        error : Exception"""

        if hasattr(ctx.command, "on_error"):  # ローカルのハンドリングがあるコマンドは除く
            return

        if isinstance(error, commands.CommandNotFound):
            return

        elif isinstance(error, commands.DisabledCommand):
            msg = await ctx.reply(f"{ctx.command} has been disabled.")
            await self.delete_after(msg)
            return

        elif isinstance(error, commands.CheckFailure):
            await ctx.reply(f"you have no permission to execute {ctx.command}.")
            return

        elif isinstance(error, commands.NoPrivateMessage):
            try:
                return await ctx.reply(f"{ctx.command} can not be used in Private Messages.")
            except discord.HTTPException:
                print("couldn't send direct message")

        elif isinstance(error, commands.BadArgument):
            msg = await ctx.reply("無効な引数です")
            await self.delete_after(msg)

        elif isinstance(error, commands.MissingRequiredArgument):
            msg = await ctx.reply("引数が足りません")
            await self.delete_after(msg)

        else:
            error = getattr(error, "original", error)
            print("Ignoring exception in command {}:".format(ctx.command), file=sys.stderr)
            traceback.print_exception(type(error), error, error.__traceback__, file=sys.stderr)
            error_content = f"error content: {error}\nmessage_content: {ctx.message.content}\nmessage_author : {ctx.message.author}\n{ctx.message.jump_url}"

            logging.error(error_content, exc_info=True)

    @commands.Cog.listener()
    async def on_application_command_error(self, ctx, error):
        """
        The event triggered when an error is raised while invoking a command.
        ctx   : Context
        error : Exception
        """

        if isinstance(error, commands.errors.MissingPermissions):
            await ctx.respond(f"you have no permission to execute {ctx.command.name}.")
            logging.error(
                f"権限エラー: {ctx.author}\nguild: {ctx.interaction.guild}\nchannel: {ctx.interaction.channel}",
                exc_info=True,
            )
            return

        elif isinstance(error.original, commands.errors.MessageNotFound):
            await ctx.respond("message not found.", delete_after=5)
            return

        else:
            error = getattr(error, "original", error)
            print("Ignoring exception in command {}:".format(ctx.command), file=sys.stderr)
            traceback.print_exception(type(error), error, error.__traceback__, file=sys.stderr)
            error_content = f"error content: {error}\nmessage_content: {ctx.command.name}\nmessage_author : {ctx.author}\nguild: {ctx.interaction.guild}\nchannnel: {ctx.interaction.channel}"

            logging.error(error_content, exc_info=True)


async def setup(bot):
    await bot.add_cog(CommandErrorHandler(bot))
